<?xml version="1.0"?>
<robot name="gojo_robot" xmlns:xacro="http://www.ros.org/wiki/xacro">

    <material name="green">
        <color rgba="0 0.5 0 1.0" />
    </material>
    <material name="grey">
        <color rgba="0.5 0.5 0.5 1" />
    </material>
    <material name="black">
        <color rgba="0 0 0 1" />
    </material>

    <link name="base_footprint">
    </link>
    <link name="base_link">
        <visual>
            <geometry>
                <mesh filename="package://gojo_description/meshes/chassis.stl" />
            </geometry>
            <origin xyz="0 0 0" rpy="0 0 0" />
            <material name="green" />
        </visual>
        <collision>
            <geometry>
                <box size="2.579053 1.183461 0.622474" />
            </geometry>
            <origin xyz="0 0 0" rpy="0 0 0" />
        </collision>
        <inertial>
            <mass value="1.0" />
            <origin xyz="0.246856 -0.000080 -0.000820" rpy="3.1416 -0.000377 3.1416" />
            <inertia ixx="0.251775" ixy="0.000000" ixz="0.0000000" 
                     iyy="0.743608" iyz="0.000000" 
                     izz="0.929233" />
        </inertial>
    </link>


    <joint name="base_joint" type="fixed">
        <parent link="base_footprint" />
        <child link="base_link" />
        <origin xyz="0 0 0.5" rpy="0 0 0" />
    </joint>
 
    <link name="left_front_wheel_link">
        <visual>
            <geometry>
                <mesh filename="package://gojo_description/meshes/tire.stl" />
            </geometry>
            <origin xyz="0 0 0" rpy="0 0 0" />
            <material name="black" />
        </visual>
        <collision>
            <geometry>
                <cylinder radius="0.5" length="0.371" />
            </geometry>
            <origin xyz="0 0 0" rpy="1.57 0 0" />
        </collision>
        <inertial>
            <mass value="1.0" />
            <origin xyz="-0.000272 0.027165 0.001936" rpy="3.1416 -0.001123 3.1416" />
            <inertia ixx="0.016741" ixy="0.000001" ixz="-0.000000" 
                     iyy="0.029620" iyz="-0.000015" 
                     izz="0.016693" />
        </inertial>
    </link> 
    <joint name="base_left_front_wheel_joint" type="continuous">
        <parent link="base_link" />
        <child link="left_front_wheel_link" />
        <origin xyz="-0.3 -0.75 0" rpy="0 0 0" />
        <axis xyz="0 -1 0" />
    </joint>

    <link name="left_back_wheel_link">
        <visual>
            <geometry>
                <mesh filename="package://gojo_description/meshes/tire.stl" />
            </geometry>
            <origin xyz="0 0 0" rpy="0 0 0" />
            <material name="black" />
        </visual>
        <collision>
            <geometry>
                <cylinder radius="0.5" length="0.371" />
            </geometry>
            <origin xyz="0 0 0" rpy="1.57 0 0" />
        </collision>
        <inertial>
            <mass value="1.0" />
            <origin xyz="-0.000272 0.027165 0.001936" rpy="3.1416 -0.001123 3.1416" />
            <inertia ixx="0.016741" ixy="0.000001" ixz="-0.000000" 
                     iyy="0.029620" iyz="-0.000015" 
                     izz="0.016693" />
        </inertial>
    </link> 
    <joint name="base_left_back_wheel_joint" type="continuous">
        <parent link="base_link" />
        <child link="left_back_wheel_link" />
        <origin xyz="1.0 -0.75 0" rpy="0 0 0" />
        <axis xyz="0 -1 0" />
    </joint>

    <link name="right_front_wheel_link">
        <visual>
            <geometry>
                <mesh filename="package://gojo_description/meshes/tire.stl" />
            </geometry>
            <origin xyz="0 0 0" rpy="0 0 3.14" />
            <material name="black" />
        </visual>
        <collision>
            <geometry>
                <cylinder radius="0.5" length="0.371" />
            </geometry>
            <origin xyz="0 0 0" rpy="1.57 0 0" />
        </collision>
        <inertial>
            <mass value="1.0" />
            <origin xyz="-0.000272 0.027165 0.001936" rpy="3.1416 -0.001123 3.1416" />
            <inertia ixx="0.016741" ixy="0.000001" ixz="-0.000000" 
                     iyy="0.029620" iyz="-0.000015" 
                     izz="0.016693" />
        </inertial>
    </link> 
    <joint name="base_right_front_wheel_joint" type="continuous">
        <parent link="base_link" />
        <child link="right_front_wheel_link" />
        <origin xyz="-0.3 0.75 0" rpy="0 0 0" />
        <axis xyz="0 -1 0" />
    </joint>

    <link name="right_back_wheel_link">
        <visual>
            <geometry>
                <mesh filename="package://gojo_description/meshes/tire.stl" />
            </geometry>
            <origin xyz="0 0 0" rpy="0 0 3.14" />
            <material name="black" />
        </visual>
        <collision>
            <geometry>
                <cylinder radius="0.5" length="0.371" />
            </geometry>
            <origin xyz="0 0 0" rpy="1.57 0 0" />
        </collision>
        <inertial>
            <mass value="1.0" />
            <origin xyz="-0.000272 0.027165 0.001936" rpy="3.1416 -0.001123 3.1416" />
            <inertia ixx="0.016741" ixy="0.000001" ixz="-0.000000" 
                     iyy="0.029620" iyz="-0.000015" 
                     izz="0.016693" />
        </inertial>
    </link> 
    <joint name="base_right_back_wheel_joint" type="continuous">
        <parent link="base_link" />
        <child link="right_back_wheel_link" />
        <origin xyz="1.0 0.75 0" rpy="0 0 0" />
        <axis xyz="0 -1 0" />
    </joint>

    <link name="ultrasonic_sensor_link">
        <visual>
            <geometry>
                <mesh filename="package://gojo_description/meshes/u_sensor.stl" />
            </geometry>
            <origin xyz="0 0 0" rpy="0 0 0" />
            <material name="grey" />
        </visual>
        <collision>
            <geometry>
                <box size="0.385456 0.186298 0.232044" />
            </geometry>
            <origin xyz="0 0 0" rpy="0 0 0" />
        </collision>
        <inertial>
            <mass value="0.25" />
            <origin xyz="-0.009628 -0.000085 0.021108" rpy="0.012 -0.591 1.569" />
            <inertia ixx="0.000139" ixy="-0.000000" ixz="0.000025" 
                     iyy="0.000081" iyz="0.000000" 
                     izz="0.000123" />
        </inertial>
    </link> 
    <joint name="base_ultrasonic_sensor_joint" type="fixed">
        <parent link="base_link" />
        <child link="ultrasonic_sensor_link" />
        <origin xyz="-0.8 0 0.5" rpy="0 0 0" />
    </joint>
    
    <link name="raspberry_stand_link">
        <visual>
            <geometry>
                <mesh filename="package://gojo_description/meshes/pi_stand.stl" />
            </geometry>
            <origin xyz="0 0 0" rpy="0 0 1.57" />
            <material name="grey" />
        </visual>
        <collision>
            <geometry>
                <box size="0.819344 0.682982 0.44900" />
            </geometry>
            <origin xyz="0 0 0" rpy="0 0 1.57" />
        </collision>
        <inertial>
            <mass value="0.5" />
            <origin xyz="0.000000 0.000000 0.000000" rpy="0 0 1.57" />
            <inertia ixx="0.036371" ixy="0.000000" ixz="0.000000" 
                     iyy="0.027836" iyz="0.000000" 
                     izz="0.047407" />
        </inertial>
    </link> 
    <joint name="base_raspberry_stand_joint" type="fixed">
        <parent link="base_link" />
        <child link="raspberry_stand_link" />
        <origin xyz="-0.1 0 0.6" rpy="0 0 0" />
    </joint>

    <link name="camera_stand_link">
        <visual>
            <geometry>
                <mesh filename="package://gojo_description/meshes/cam_stand.stl" />
            </geometry>
            <origin xyz="0 0 0" rpy="0 0 0" />
            <material name="grey" />
        </visual>
        <collision>
            <geometry>
                <box size="0.444509 0.378892 0.864679" />
            </geometry>
            <origin xyz="0 0 0" rpy="0 0 0" />
        </collision>
        <inertial>
            <mass value="0.25" />
            <origin xyz="0.002037 0.000000 0.034920" rpy="1.5708 0.012 0" />
            <inertia ixx="0.001652" ixy="0.000000" ixz="0.000011" 
                     iyy="0.001518" iyz="0.000000" 
                     izz="0.000759" />
        </inertial>
    </link> 
    <joint name="base_camera_stand_joint" type="fixed">
        <parent link="base_link" />
        <child link="camera_stand_link" />
        <origin xyz="0.7 0 0.9" rpy="0 0 0" />
    </joint>
   
</robot>
